Workbook

Sheet TestScenario
B3: Project Name | C3: HRM System
B4: Client | C4: XXX
B5: Reference Document | C5: SRS
B6: Created By | C6: XXX
B7: Creation Date | C7: 45881
B8: Approval Date | C8: DD-MM-YYYY
B10: Test Scenario ID | C10: References | D10: Test Scenario Description | E10: Priority | F10: Number of Tests | G10: Number of Passed Tests | H10: Number of Failed Tests | I10: Number of Not Tested Tests | J10: Number of Fixed Tests
B11: (TS-001) Login Functionality | C11: SRS | D11: Validate the Working of Login Functionality | E11: P0 | F11: =COUNTA(LoginFunctionality!A3:A1000) -> 19 | G11: =COUNTIF(LoginFunctionality!I:I, "Pass") -> 11 | H11: =COUNTIF(LoginFunctionality!I:I, "Fail") -> 0 | I11: =COUNTIF(LoginFunctionality!I:I, "Not Tested") -> 8 | J11: =COUNTIF(LoginFunctionality!I:I, "Fixed") -> 0
B12: (TS-002) Registration Functionality | C12: SRS | D12: Validate the working of Registration Functionality | E12: P0 | F12: =COUNTA(RegistrationFunctionality!A3:A1000) -> 24 | G12: =COUNTIF(RegistrationFunctionality!I:I, "Pass") -> 0 | H12: =COUNTIF(RegistrationFunctionality!I:I, "Fail") -> 0 | I12: =COUNTIF(RegistrationFunctionality!I:I, "Not Tested") -> 24 | J12: =COUNTIF(RegistrationFunctionality!I:I, "Fixed") -> 0
B13: (TS-003) Password Management | C13: SRS | D13: Validate the working of Password Management Functionality | E13: P0 | F13: =COUNTA(PasswordManagement!A3:A1000) -> 43 | G13: =COUNTIF(PasswordManagement!I:I, "Pass") -> 0 | H13: =COUNTIF(PasswordManagement!I:I, "Fail") -> 0 | I13: =COUNTIF(PasswordManagement!I:I, "Not Tested") -> 43 | J13: =COUNTIF(PasswordManagement!I:I, "Fixed") -> 0
B14: (TS-004) Forgot Password | C14: SRS | D14: Validate the working of Forgot Password Functionality | E14: P0 | F14: =COUNTA(ForgotPassword!A3:A1000) -> 10 | G14: =COUNTIF(ForgotPassword!I:I, "Pass") -> 0 | H14: =COUNTIF(ForgotPassword!I:I, "Fail") -> 0 | I14: =COUNTIF(ForgotPassword!I:I, "Not Tested") -> 10 | J14: =COUNTIF(ForgotPassword!I:I, "Fixed") -> 0
B15: (TS-005) Session Management | C15: SRS | D15: Validate the working of Session Management Functionality | E15: P0 | F15: =COUNTA(SessionManagement!A3:A1000) -> 1 | G15: =COUNTIF(SessionManagement!I:I, "Pass") -> #REF! | H15: =COUNTIF(SessionManagement!I:I, "Fail") -> #REF! | I15: =COUNTIF(SessionManagement!I:I, "Not Tested") -> #REF! | J15: =COUNTIF(SessionManagement!I:I, "Fixed") -> #REF!
B16: (TS-006) RBAC Functionality | C16: SRS | D16: Validate the working of Role Based Access Control Functionality | E16: P0 | F16: =COUNTA(RBACFunctionality!A3:A1000) -> 16 | G16: =COUNTIF(RBACFunctionality!I:I, "Pass") -> 3 | H16: =COUNTIF(RBACFunctionality!I:I, "Fail") -> 0 | I16: =COUNTIF(RBACFunctionality!I:I, "Not Tested") -> 13 | J16: =COUNTIF(RBACFunctionality!I:I, "Fixed") -> 0
B17: (TS-007) Log & Audit Functionality | C17: SRS | D17: Validate the working of Log & Audit Functionality | E17: P0 | F17: =COUNTA(LogAuditFunctionality!A3:A1000) -> 35 | G17: =COUNTIF(LogAuditFunctionality!I:I, "Pass") -> 0 | H17: =COUNTIF(LogAuditFunctionality!I:I, "Fail") -> 0 | I17: =COUNTIF(LogAuditFunctionality!I:I, "Not Tested") -> 35 | J17: =COUNTIF(LogAuditFunctionality!I:I, "Fixed") -> 0
B18: (TS-008) Suspicious Activity Detection Functionality | C18: SRS | D18: Validate the working of Suspicious Activity Detection Functionality | E18: P0 | F18: =COUNTA(SADFunctionality!A3:A1000) -> 1 | G18: =COUNTIF(SADFunctionality!I:I, "Pass") -> #REF! | H18: =COUNTIF(SADFunctionality!I:I, "Fail") -> #REF! | I18: =COUNTIF(SADFunctionality!I:I, "Not Tested") -> #REF! | J18: =COUNTIF(SADFunctionality!I:I, "Fixed") -> #REF!
B19: (TS-009) API Functionality | C19: SRS | D19: Validate the working of API Functionality | E19: P0 | F19: =APIFunctionality!F14 -> 508 | G19: =APIFunctionality!G14 -> #REF! | H19: =APIFunctionality!H14 -> #REF! | I19: =APIFunctionality!I14 -> #REF! | J19: =APIFunctionality!J14 -> #REF!
B20: TOTAL | F20: =SUM(F11:F19) -> 657 | G20: =SUM(G11:G19) -> #REF! | H20: =SUM(H11:H19) -> #REF! | I20: =SUM(I11:I19) -> #REF! | J20: =SUM(J11:J19) -> #REF!

Sheet APIFunctionality
B2: <<<TestScenario
B3: Test Scenario ID | C3: References | D3: Test Scenario Description | E3: Priority | F3: Number of Tests | G3: Number of Passed Tests | H3: Number of Failed Tests | I3: Number of Not Tested Tests | J3: Number of Fixed Tests
B4: (TS-API-001) Auth API Functionality | C4: SRS | D4: Validate the Working of Authorization API Functionality | E4: P0 | F4: =AuthAPI!F10 -> 71 | G4: =AuthAPI!G10 -> #REF! | H4: =AuthAPI!H10 -> #REF! | I4: =AuthAPI!I10 -> #REF! | J4: =AuthAPI!J10 -> #REF!
B5: (TS-API-002) Checklists API Functionality | C5: SRS | D5: Validate the Working of Checklist API Functionality | E5: P0 | F5: =COUNTA(ChecklistAPI!A4:A1004) -> 74 | G5: =COUNTIF(ChecklistAPI!K:K, "Pass") -> 56 | H5: =COUNTIF(ChecklistAPI!K:K, "Fail") -> 2 | I5: =COUNTIF(ChecklistAPI!K:K, "Not Tested") -> 11 | J5: =COUNTIF(ChecklistAPI!K:K, "Fixed") -> 0
B6: (TS-API-003) Department API Functionality | C6: SRS | D6: Validate the Working of Department API Functionality | E6: P0 | F6: =COUNTA(DepartmentAPI!A4:A1004) -> 88 | G6: =COUNTIF(DepartmentAPI!K:K, "Pass") -> 62 | H6: =COUNTIF(DepartmentAPI!K:K, "Fail") -> 0 | I6: =COUNTIF(DepartmentAPI!K:K, "Not Tested") -> 21 | J6: =COUNTIF(DepartmentAPI!K:K, "Fixed") -> 0
B7: (TS-API-004) File API Functionality | C7: SRS | D7: Validate the Working of File API Functionality | E7: P0 | F7: =COUNTA(FileAPI!A4:A1004) -> 37 | G7: =COUNTIF(FileAPI!K:K, "Pass") -> 25 | H7: =COUNTIF(FileAPI!K:K, "Fail") -> 3 | I7: =COUNTIF(FileAPI!K:K, "Not Tested") -> 9 | J7: =COUNTIF(FileAPI!K:K, "Fixed") -> 0
B8: (TS-API-005) User API Functionality | C8: SRS | D8: Validate the Working of User API Functionality | E8: P0 | F8: =COUNTA(UserAPI!A4:A1004) -> 38 | G8: =COUNTIF(UserAPI!K:K, "Pass") -> 17 | H8: =COUNTIF(UserAPI!K:K, "Fail") -> 1 | I8: =COUNTIF(UserAPI!K:K, "Not Tested") -> 20 | J8: =COUNTIF(UserAPI!K:K, "Fixed") -> 0
B9: (TS-API-006) User Profile API Functionality | C9: SRS | D9: Validate the Working of User Profile API Functionality | E9: P0 | F9: =COUNTA(UserProfileAPI!A4:A1004) -> 121 | G9: =COUNTIF(UserProfileAPI!K:K, "Pass") -> 102 | H9: =COUNTIF(UserProfileAPI!K:K, "Fail") -> 2 | I9: =COUNTIF(UserProfileAPI!K:K, "Not Tested") -> 12 | J9: =COUNTIF(UserProfileAPI!K:K, "Fixed") -> 0
B10: (TS-API-007) Admin API Functionality | C10: SRS | D10: Validate the workin of Admin API Functionality | E10: P0 | F10: =COUNTA(AdminAPI!A4:A1004) -> 33 | G10: =COUNTIF(AdminAPI!K:K, "Pass") -> 23 | H10: =COUNTIF(AdminAPI!K:K, "Fail") -> 0 | I10: =COUNTIF(AdminAPI!K:K, "Not Tested") -> 10 | J10: =COUNTIF(AdminAPI!K:K, "Fixed") -> 0
B11: (TS-API-008) Entity Type API Functionality | C11: SRS | D11: Validate the working of Entity Type API Functionality | E11: P0 | F11: =COUNTA(EntityTypeAPI!A5:A1004) -> 14 | G11: =COUNTIF(EntityTypeAPI!K:K, "Pass") -> 13 | H11: =COUNTIF(EntityTypeAPI!K:K, "Fail") -> 0 | I11: =COUNTIF(EntityTypeAPI!K:K, "Not Tested") -> 2 | J11: =COUNTIF(EntityTypeAPI!K:K, "Fixed") -> 0
B12: (TS-API-009) Document API Functionality | C12: SRS | D12: Validate the Working of Document API Functionality | E12: P0 | F12: =COUNTA(DocumentAPI!A4:A1004) -> 31 | G12: =COUNTIF(DocumentAPI!K:K, "Pass") -> 12 | H12: =COUNTIF(DocumentAPI!K:K, "Fail") -> 0 | I12: =COUNTIF(DocumentAPI!K:K, "Not Tested") -> 19 | J12: =COUNTIF(DocumentAPI!K:K, "Fixed") -> 0
B13: (TS-API-010) UserChecklist API Functionality | C13: SRS | D13: Validate the Working of UserChecklist API Functionality | E13: P0 | F13: =COUNTA(UserChecklistAPI!A4:A1004) -> 1 | G13: =COUNTIF(UserChecklistAPI!K:K, "Pass") -> #REF! | H13: =COUNTIF(UserChecklistAPI!K:K, "Fail") -> #REF! | I13: =COUNTIF(UserChecklistAPI!K:K, "Not Tested") -> #REF! | J13: =COUNTIF(UserChecklistAPI!K:K, "Fixed") -> #REF!
B14: TOTAL | F14: =SUM(F4:F13) -> 508 | G14: =SUM(G4:G13) -> #REF! | H14: =SUM(H4:H13) -> #REF! | I14: =SUM(I4:I13) -> #REF! | J14: =SUM(J4:J13) -> #REF!

Sheet AuthAPI
B2: <<<TestScenario | C2: <<<APITestScenario
B3: Test Scenario ID | C3: References | D3: Test Scenario Description | E3: Priority | F3: Number of Tests | G3: Number of Passed Tests | H3: Number of Failed Tests | I3: Number of Not Tested Tests | J3: Number of Fixed Tests
B4: (TS-AUTH-API-001) Login API Functionality | C4: SRS | D4: Validate the Working of Login API Functionality | E4: P0 | F4: =COUNTA(LoginAPI!B4:B997) -> 12 | G4: =COUNTIF(LoginAPI!K:K, "Pass") -> 11 | H4: =COUNTIF(LoginAPI!K:K, "Fail") -> 1 | I4: =COUNTIF(LoginAPI!K:K, "Not Tested") -> 0 | J4: =COUNTIF(LoginAPI!K:K, "Fixed") -> 0
B5: (TS-AUTH-API-002) Logout API Functionality | C5: SRS | D5: Validate the Working of Logout API Functionality | E5: P0 | F5: =COUNTA(LogoutAPI!B4:B997) -> 7 | G5: =COUNTIF(LogoutAPI!K:K, "Pass") -> 7 | H5: =COUNTIF(LogoutAPI!K:K, "Fail") -> 0 | I5: =COUNTIF(LogoutAPI!K:K, "Not Tested") -> 0 | J5: =COUNTIF(LogoutAPI!K:K, "Fixed") -> 0
B6: (TS-AUTH-API-003) Forgot Password API Functionality | C6: SRS | D6: Validate the Working of Forgot Passowrd API Functionality | E6: P0 | F6: =COUNTA(ForgotPasswordAPI!B4:B997) -> 15 | G6: =COUNTIF(ForgotPasswordAPI!K:K, "Pass") -> 13 | H6: =COUNTIF(ForgotPasswordAPI!K:K, "Fail") -> 0 | I6: =COUNTIF(ForgotPasswordAPI!K:K, "Not Tested") -> 2 | J6: =COUNTIF(ForgotPasswordAPI!K:K, "Fixed") -> 0
B7: (TS-AUTH-API-004) Token API Functionality | C7: SRS | D7: Validate the Working of Token API Functionality | E7: P0 | F7: =COUNTA(TokenAPI!B4:B997) -> 10 | G7: =COUNTIF(TokenAPI!K:K, "Pass") -> 9 | H7: =COUNTIF(TokenAPI!K:K, "Fail") -> 0 | I7: =COUNTIF(TokenAPI!K:K, "Not Tested") -> 1 | J7: =COUNTIF(TokenAPI!K:K, "Fixed") -> 0
B8: (TS-AUTH-API-005) Reset Password API Functionality | C8: SRS | D8: Validate the Working of Reset Password API Functionality | E8: P0 | F8: =COUNTA(ResetPasswordAPI!B4:B997) -> 1 | G8: =COUNTIF(ResetPasswordAPI!L:L, "Pass") -> #REF! | H8: =COUNTIF(ResetPasswordAPI!L:L, "Fail") -> #REF! | I8: =COUNTIF(ResetPasswordAPI!L:L, "Not Tested") -> #REF! | J8: =COUNTIF(ResetPasswordAPI!L:L, "Fixed") -> #REF!
B9: (TS-AUTH-API-006) Set Password API Functionality | C9: SRS | D9: Validate the Working of Set Password API Functionality | E9: P0 | F9: =COUNTA(SetPasswordAPI!B4:B997) -> 26 | G9: =COUNTIF(SetPasswordAPI!K:K, "Pass") -> 13 | H9: =COUNTIF(SetPasswordAPI!K:K, "Fail") -> 0 | I9: =COUNTIF(SetPasswordAPI!K:K, "Not Tested") -> 13 | J9: =COUNTIF(SetPasswordAPI!K:K, "Fixed") -> 0
B10: TOTAL | F10: =SUM(F4:F9) -> 71 | G10: =SUM(G4:G9) -> #REF! | H10: =SUM(H4:H9) -> #REF! | I10: =SUM(I4:I9) -> #REF! | J10: =SUM(J4:J9) -> #REF!

Sheet EntityTypeAPI
A1: <<<TestScenario | B1: <<<APITestScenario
A2: Test Case ID | B2: Test Scenario | C2: Test Case Title | D2: Method | E2: API Endpoints | F2: Test Data | G2: Pre-requisites | H2: Test Steps | I2: Expected Result | J2: Actual Result | K2: Execution Status | L2: Severity | M2: Priority | N2: Attachments | O2: Notes
B3: Fetch List of User Metadata
A4: API-FETCH-METADATA-001 | B4: (TS-API-008) Entity Type API Functionality | C4: Fetch metadata successfully | D4: GET | E4: /v1/users/metadata | F4: Valid Auth Token | G4: User logged in | H4: Send GET request | I4: Status Code "200 OK" with metadata response | J4: List of metadata is displayed | K4: Pass | L4: High | M4: High | O4: Positive case
A5: API-FETCH-METADATA-002 | B5: (TS-API-008) Entity Type API Functionality | C5: Validate response structure | D5: GET | E5: /v1/users/metadata | F5: Valid Token | G5: User logged in | H5: Send request | I5: Response contains userType, userStatus, role, gender arrays | J5: As expectced | K5: Pass | L5: High | M5: High | O5: Schema validation
A6: API-FETCH-METADATA-003 | B6: (TS-API-008) Entity Type API Functionality | C6: Validate array object structure | D6: GET | E6: /v1/users/metadata | F6: Valid Token | G6: User logged in | H6: Send request | I6: Each object contains value, name, title | J6: As expectced | K6: Pass | L6: Medium | M6: High | O6: Field validation
A7: API-FETCH-METADATA-004 | B7: (TS-API-008) Entity Type API Functionality | C7: Validate value datatype | D7: GET | E7: /v1/users/metadata | F7: Valid Token | G7: User logged in | H7: Send request | I7: value is string | J7: As expectced | K7: Pass | L7: Medium | M7: Medium | O7: Data type check
A8: API-FETCH-METADATA-005 | B8: (TS-API-008) Entity Type API Functionality | C8: Validate name format | D8: GET | E8: /v1/users/metadata | F8: Valid Token | G8: User logged in | H8: Send request | I8: name is uppercase (e.g., FULLTIME) | J8: As expectced | K8: Pass | L8: Low | M8: Low | O8: Format consistency
A9: API-FETCH-METADATA-006 | B9: (TS-API-008) Entity Type API Functionality | C9: Validate title format | D9: GET | E9: /v1/users/metadata | F9: Valid Token | G9: User logged in | H9: Send request | I9: title is human-readable (e.g., Fulltime) | J9: As expectced | K9: Pass | L9: Low | M9: Low | O9: UI validation
A10: API-FETCH-METADATA-007 | B10: (TS-API-008) Entity Type API Functionality | C10: Empty metadata arrays | D10: GET | E10: /v1/users/metadata | F10: Valid Token | G10: No metadata configured | H10: Send request | I10: Returns empty arrays, not null | J10: As expectced | K10: Pass | L10: Medium | M10: Medium | O10: Edge case
A11: API-FETCH-METADATA-008 | B11: (TS-API-008) Entity Type API Functionality | C11: Missing Authorization header | D11: GET | E11: /v1/users/metadata | F11: No Token | H11: Send request | I11: Status Code "401 Unauthorized" with Unauthenticated message | J11: Unauthorized message displayed | K11: Pass | L11: High | M11: High | O11: Authentication
A12: API-FETCH-METADATA-009 | B12: (TS-API-008) Entity Type API Functionality | C12: Invalid JWT token | D12: GET | E12: /v1/users/metadata | F12: Tampered Token | H12: Send request | I12: Status Code "401 Unauthorized" with Unauthenticated message | J12: As expectced | K12: Pass | L12: High | M12: High | O12: Token validation
A13: API-FETCH-METADATA-010 | B13: (TS-API-008) Entity Type API Functionality | C13: Expired JWT token | D13: GET | E13: /v1/users/metadata | F13: Expired Token | H13: Send request | I13: Status Code "401 Unauthorized" with Unauthenticated message | J13: As expectced | K13: Pass | L13: High | M13: High | O13: Token expiry
A14: API-FETCH-METADATA-011 | B14: (TS-API-008) Entity Type API Functionality | C14: Role-based access control | D14: GET | E14: /v1/users/metadata | F14: Limited role token | G14: Role restrictions applied | H14: Send request | I14: Status Code "403 Forbidden" with proper message (If Restricted) | K14: Not tested | L14: High | M14: High | O14: Authorization
A15: API-FETCH-METADATA-012 | B15: (TS-API-008) Entity Type API Functionality | C15: Response time under normal load | D15: GET | E15: /v1/users/metadata | F15: Valid Token | G15: Normal system load | H15: Send request | I15: Response ≤ 2 seconds | J15: As expected | K15: Pass | L15: Low | M15: Low | O15: SLA check
A16: API-FETCH-METADATA-013 | B16: (TS-API-008) Entity Type API Functionality | C16: Response under high load | D16: GET | E16: /v1/users/metadata | F16: Valid Token | G16: 100+ concurrent users | H16: Execute load test | I16: No timeout, stable response | K16: Not tested | L16: Medium | M16: Medium | O16: Load testing
A17: API-FETCH-METADATA-014 | B17: (TS-API-008) Entity Type API Functionality | C17: Database failure handling | D17: GET | E17: /v1/users/metadata | F17: Valid Token | G17: DB unavailable | H17: Send request | I17: Status Code "500 Internal Server Error" | J17: As expected | K17: Pass | L17: High | M17: High | O17: Error handling
A18: API-FETCH-METADATA-015 | B18: (TS-API-008) Entity Type API Functionality | C18: Validate no duplicate values in arrays | D18: GET | E18: /v1/users/metadata | F18: Valid Token | G18: Metadata configured | H18: Send request | I18: No duplicate "value" fields | J18: As expected | K18: Pass | L18: Medium | M18: Medium | O18: Data consistency

Sheet DocumentAPI
A1: <<<TestScenario | B1: <<<APITestScenario
A2: Test Case ID | B2: Test Scenario | C2: Test Case Title | D2: Method | E2: API Endpoints | F2: Test Data | G2: Pre-requisites | H2: Test Steps | I2: Expected Result | J2: Actual Result | K2: Execution Status | L2: Severity | M2: Priority | N2: Attachments | O2: Notes
B3: Return All Document Detail
A4: API-GET-DOCUMENT-001 | B4: (TS-API-009) Document API Functionality | C4: Verify the document is returned | D4: GET | E4: /v1/documents/{user} | F4: valid token, valid ulid of users | G4: user logged in an , user with ulid exist | H4: 1. Send GET request with valid ulid | I4: Status Code "200 OK" and document returned | J4: Documents related to valid ULID returned | K4: Pass | L4: N/A | M4: N/A | O4: Positive test case
A5: API-GET-DOCUMENT-002 | B5: (TS-API-009) Document API Functionality | C5: Verify that the document number is returned in response | D5: GET | E5: /v1/documents/{user} | F5: valid token, valid ulid of users | G5: user logged in an , user with ulid exist | H5: 1. Send GET request with valid ulid | I5: Status Code "200 OK" and response contains document no | J5: As expected | K5: Pass | L5: N/A | M5: N/A | O5: Positive test case
A6: API-GET-DOCUMENT-003 | B6: (TS-API-009) Document API Functionality | C6: Verify that the response contain file ulid and file path | D6: GET | E6: /v1/documents/{user} | F6: valid token, valid ulid of users | G6: user logged in an , user with ulid exist and document also exist | H6: 1. Send GET request with valid ulid | I6: Status Code "200 OK" and response contains file ulid and file path | J6: As expected | K6: Pass | L6: N/A | M6: N/A
A7: API-GET-DOCUMENT-004 | B7: (TS-API-009) Document API Functionality | C7: Verify that the file path is correct and file is available | D7: GET | E7: /v1/documents/{user} | F7: valid token, valid ulid of users | G7: user logged in an , user with ulid exist and file also exist | H7: 1. Send GET request with valid ulid | I7: File path is correct and file is avilabe at that url | K7: Not tested | L7: N/A | M7: N/A
A8: API-GET-DOCUMENT-005 | B8: (TS-API-009) Document API Functionality | C8: Verify unauthorized access | D8: GET | E8: /v1/documents/{user} | F8: No token, valid ulid of user | H8: 1. Send GET request without authentication header | I8: Status Code "401 Unauthorized" with Unauthenticated message | J8: Unauthorized message displayed | K8: Pass | L8: N/A | M8: N/A
A9: API-GET-DOCUMENT-006 | B9: (TS-API-009) Document API Functionality | C9: Verify access with invalid token | D9: GET | E9: /v1/documents/{user} | F9: Expired token, valid ulid | G9: User exists | H9: 1. Send GET with expired token | I9: Status Code "401 Unauthorized" with Unauthenticated message | J9: As expected | K9: Pass | L9: N/A | M9: N/A
A10: API-GET-DOCUMENT-007 | B10: (TS-API-009) Document API Functionality | C10: Verify access with expired token | D10: GET | E10: /v1/documents/{user} | F10: Invalid token, valid ulid | G10: None | H10: 1. Send GET with invalid token | I10: Status Code "401 Unauthorized" with Unauthenticated message | J10: As expected | K10: Pass | L10: N/A | M10: N/A
A11: API-GET-DOCUMENT-008 | B11: (TS-API-009) Document API Functionality | C11: Verify access with insufficient role | D11: GET | E11: /v1/documents/{user} | F11: Valid token (different user), valid ulid | G11: Logged in as another user | H11: 1. Send GET request | I11: Status Code "403 Forbidden" with Proper Message | K11: Not tested | L11: N/A | M11: N/A | O11: Role-based access control
A12: API-GET-DOCUMENT-009 | B12: (TS-API-009) Document API Functionality | C12: Verify behaviour when ulid does not exist | D12: GET | E12: /v1/documents/{user} | F12: Valid token, non-existing ulid | G12: Logged in | H12: 1. Send GET with random ulid | I12: Status Code "404 Not Found" with Proper Message | J12: As expected | K12: Pass | L12: N/A | M12: N/A
A13: API-GET-DOCUMENT-010 | B13: (TS-API-009) Document API Functionality | C13: Verify when ulid parameter is empty | D13: GET | E13: /v1/documents/{user} | F13: Valid token, empty ulid | G13: Logged in | H13: 1. Send GET without ulid | I13: Status Code "404 Not Found" with proper message | J13: As expected | K13: Pass | L13: N/A | M13: N/A
A14: API-GET-DOCUMENT-011 | B14: (TS-API-009) Document API Functionality | C14: Verify response contains correct ULID | D14: GET | E14: /v1/documents/{user} | F14: Valid token, valid ulid | G14: User + document exists | H14: 1. Send GET request | I14: Response ULID matches requested ULID | J14: As expected | K14: Pass | L14: N/A | M14: N/A
A15: API-GET-DOCUMENT-012 | B15: (TS-API-009) Document API Functionality | C15: Verify file object structure | D15: GET | E15: /v1/documents/{user} | F15: Valid token | G15: Document exists | H15: 1. Send GET request | I15: Response contains file.ulid and file.filePath | J15: As expected | K15: Pass | L15: N/A | M15: N/A
A16: API-GET-DOCUMENT-013 | B16: (TS-API-009) Document API Functionality | C16: Verify file path is accessible | D16: GET | E16: /v1/documents/{user} | F16: Valid token | G16: File exists | H16: 1. Send GET 2. Open filePath URL | I16: File loads successfully (200 OK) | K16: Not tested | L16: N/A | M16: N/A
A17: API-GET-DOCUMENT-014 | B17: (TS-API-009) Document API Functionality | C17: Verify response time is under normal load | D17: GET | E17: /v1/documents/{user} | F17: Valid token | G17: System running normally | H17: 1. Send GET request | I17: Response time < 2 seconds | J17: As expected | K17: Pass | L17: N/A | M17: N/A
A18: API-GET-DOCUMENT-015 | B18: (TS-API-009) Document API Functionality | C18: Verify response header content-type | D18: GET | E18: /v1/documents/{user} | F18: Valid token | G18: Document exists | H18: 1. Send GET request | I18: Content-Type: application/json | J18: As expected | K18: Pass | L18: N/A | M18: N/A
B19: Update an existing document
A20: API-UPDATE-DOCUMENT-016 | B20: (TS-API-009) Document API Functionality | C20: Update the documents with all valid files | D20: PUT | E20: /v1/documents/:user | F20: Valid body request with citizenshipNo, citizenshipFront, citizenshipBack, panNo, pan, resume and certificates | G20: User exists | H20: 1. Call API with valid ULID and all valid file ULIDs | I20: Status Code "200 OK" | K20: Not tested | L20: N/A | M20: N/A
A21: API-UPDATE-DOCUMENT-017 | B21: (TS-API-009) Document API Functionality | C21: Update documents without authorization token | D21: PUT | E21: /v1/documents/:user | F21: Same as valid | G21: User exists | H21: 1. Call API without Auth token | I21: Status Code "401 Unauthorized" with Unauthenticated message | K21: Not tested | L21: N/A | M21: N/A
A22: API-UPDATE-DOCUMENT-018 | B22: (TS-API-009) Document API Functionality | C22: Update documents without ULID parameter | D22: PUT | E22: /v1/documents/:user | F22: Same as valid | G22: User exists | H22: 1. Call API endpoint without ULID in URL | I22: Status Code "404 Not Found" with Proper Message | K22: Not tested | L22: N/A | M22: N/A
A23: API-UPDATE-DOCUMENT-019 | B23: (TS-API-009) Document API Functionality | C23: Update document for non-existent user | D23: PUT | E23: /v1/documents/:user | F23: Same as valid | G23: ULID does not exist in system | H23: 1. Call API with ULID that does not exist | I23: Status Code "404 Not Found" with Proper Message | K23: Not tested | L23: N/A | M23: N/A
A24: API-UPDATE-DOCUMENT-020 | B24: (TS-API-009) Document API Functionality | C24: Update document with invalid ULID | D24: PUT | E24: /v1/documents/:user | F24: Same as valid | G24: - | H24: 1. Call API with ULID = "1234-invalid" | I24: Status Code "422 Unprocessable Entity" with Proper Message | K24: Not tested | L24: N/A | M24: N/A
A25: API-UPDATE-DOCUMENT-021 | B25: (TS-API-009) Document API Functionality | C25: Update document with missing citizenshipNo | D25: PUT | E25: /v1/documents/:user | F25: { "citizenshipFront": "...", "citizenshipBack": "...", "panNo": "PAN-987654", "pan": "...", "resume": "...", "certificates": ["..."] } | G25: User exists | H25: 1. Call API without citizenshipNo | I25: Status Code "422 Unprocessable Entity" with Proper Message | K25: Not tested | L25: N/A | M25: N/A
A26: API-UPDATE-DOCUMENT-022 | B26: (TS-API-009) Document API Functionality | C26: Update only PAN and PanNo | D26: PUT | E26: /v1/documents/:user | F26: { "panNo": "PAN-111111", "pan": "01KGEEPAEYH130EG4ZH4SJKZQ9" } | G26: User exists | H26: 1. Call API with only PAN fields | I26: Status Code "200 OK" | K26: Not tested | L26: N/A | M26: N/A
A27: API-UPDATE-DOCUMENT-023 | B27: (TS-API-009) Document API Functionality | C27: Update document without a body | D27: PUT | E27: /v1/documents/:user | F27: {} | G27: User exists | H27: 1. Call API with empty body | I27: Status Code "422 Unprocessable Entity" with Proper Message | K27: Not tested | L27: N/A | M27: N/A
B28: Add Document
A29: API-UPLOAD-DOCUMENT-024 | B29: (TS-API-009) Document API Functionality | C29: Add documents with valid bank details and documents | D29: POST | E29: /v1/documents/upload | F29: Valid bank details and required documents | G29: Authenicated user logged in | H29: 1. Call API with valid body and valid token 2. Capture response body | I29: Status Code "200 OK" , document added successfully | K29: Not tested | L29: N/A | M29: N/A
A30: API-UPLOAD-DOCUMENT-025 | B30: (TS-API-009) Document API Functionality | C30: Add document without authorization token | D30: POST | E30: /v1/documents/upload | F30: Valid bank details and required documents | G30: No token | H30: 1. Call API without auth token | I30: Status Code "401 Unauthorized" with Unauthenrticated message | K30: Not tested | L30: N/A | M30: N/A
A31: API-UPLOAD-DOCUMENT-026 | B31: (TS-API-009) Document API Functionality | C31: Add document with sufficient permissions | D31: POST | E31: /v1/documents/upload | F31: Valid bank details and required documents | G31: Authenticated user without permission | H31: 1. Call API with token that does not have access | I31: Status Code "403 Forbidden" with Proper Message | K31: Not tested | L31: N/A | M31: N/A
A32: API-UPLOAD-DOCUMENT-027 | B32: (TS-API-009) Document API Functionality | C32: Add document with missing bank details | D32: POST | E32: /v1/documents/upload | F32: bankdetails: {empty} | G32: Authenticated user logged in | H32: 1. Call API without bankDetails | I32: Status Code "422 Unprocessable Entity" with proper message | K32: Not tested | L32: N/A | M32: N/A
A33: API-UPLOAD-DOCUMENT-028 | B33: (TS-API-009) Document API Functionality | C33: Add document with missing mandatory document field | D33: POST | E33: /v1/documents/upload | F33: {} | G33: Authenticated user logged in | H33: 1. Call API without citizenshipNo or panNo | I33: Status Code "422 Unprocessable Entity" with proper message | K33: Not tested | L33: N/A | M33: N/A
A34: API-UPLOAD-DOCUMENT-029 | B34: (TS-API-009) Document API Functionality | C34: Add document with empty body | D34: POST | E34: /v1/documents/upload | F34: documents:{empty} | G34: Authenticated user logged in | H34: 1. Call API with empty JSON body | I34: Status Code "422 Unprocessable Entity" with proper message | K34: Not tested | L34: N/A | M34: N/A
A35: API-UPLOAD-DOCUMENT-030 | B35: (TS-API-009) Document API Functionality | C35: Validate bank details object in response | D35: POST | E35: /v1/documents/upload | F35: Valid bank details and required documents | G35: Authenticated user logged in | H35: 1. Call API 2. Capture response and validate all keys | I35: All bankDetails fields exist and correct | K35: Not tested | L35: N/A | M35: N/A
A36: API-UPLOAD-DOCUMENT-031 | B36: (TS-API-009) Document API Functionality | C36: Validate documents array in response | D36: POST | E36: /v1/documents/upload | F36: Valid bank details and required documents | G36: Authenticated user logged in | H36: 1. Call API 2. Verify documents array structure and keys | I36: Each document has ulid, type, documentNo, file.ulid, file.filePath | K36: Not tested | L36: N/A | M36: N/A

Sheet AdminAPI
A1: <<<TestScenario | B1: <<<APITestScenario
A2: Test Case ID | B2: Test Scenario | C2: Test Case Title | D2: Method | E2: API Endpoints | F2: Test Data | G2: Pre-requisites | H2: Test Steps | I2: Expected Result | J2: Actual Result | K2: Execution Status | L2: Severity | M2: Priority | N2: Attachments | O2: Notes
B3: Show All Existing Permissions By Model
A4: API-ADMIN-PERM-LIST-001 | B4: (TS-API-007) Admin API Functionality | C4: Retrieve all permissions successfully | D4: GET | E4: /v1/admin/permissions/list | G4: Admin authenticated | H4: Send GET request | I4: Status Code "200 OK", returns permission list grouped by model | J4: list of permission is displayed as expected | K4: Pass | L4: High | M4: High | O4: Positive case
A5: API-ADMIN-PERM-LIST-002 | B5: (TS-API-007) Admin API Functionality | C5: Validate response structure | D5: GET | E5: /v1/admin/permissions/list | G5: Admin authenticated | H5: Send GET request | I5: Response contains model keys (checklist, department, user) | J5: Response contains different model keys as expected | K5: Pass | L5: Medium | M5: High | O5: Schema validation
A6: API-ADMIN-PERM-LIST-003 | B6: (TS-API-007) Admin API Functionality | C6: Validate permission object structure | D6: GET | E6: /v1/admin/permissions/list | G6: Admin authenticated | H6: Send GET request | I6: Each permission contains id (integer) and action (string) | J6: As expected | K6: Pass | L6: Medium | M6: Medium | O6: Data type validation
A7: API-ADMIN-PERM-LIST-004 | B7: (TS-API-007) Admin API Functionality | C7: Validate multiple actions per model | D7: GET | E7: /v1/admin/permissions/list | G7: Multiple permissions exist | H7: Send GET request | I7: Returns all actions (create, update, delete, view, etc.) | J7: As expected | K7: Pass | L7: Medium | M7: Medium | O7: Coverage check
A8: API-ADMIN-PERM-LIST-005 | B8: (TS-API-007) Admin API Functionality | C8: Access without authentication | D8: GET | E8: /v1/admin/permissions/list | G8: User not logged in | H8: Send GET request | I8: Status Code "401 Unauthorized" with Unauthenticated message | J8: Unauthenticated message displayed | K8: Pass | L8: High | M8: High | O8: Security
A9: API-ADMIN-PERM-LIST-006 | B9: (TS-API-007) Admin API Functionality | C9: Access with non-admin role | D9: GET | E9: /v1/admin/permissions/list | G9: Logged in as normal user | H9: Send GET request | I9: Status Code "403 Forbidden" with proper messge | K9: Not tested | L9: High | M9: High | O9: RBAC validation
A10: API-ADMIN-PERM-LIST-007 | B10: (TS-API-007) Admin API Functionality | C10: Invalid HTTP method | D10: POST | E10: /v1/admin/permissions/list | G10: Admin authenticated | H10: Send POST request | I10: Status Code "405 Method Not Allowed" with proper message | J10: 500 Internal Server Error message displayed | K10: Pass | L10: Medium | M10: Medium | O10: Method validation
A11: API-ADMIN-PERM-LIST-008 | B11: (TS-API-007) Admin API Functionality | C11: Access with expired token | D11: GET | E11: /v1/admin/permissions/list | G11: Token expired | H11: Send GET request | I11: Status Code "401 Unauthorized" with Unauthenticated message | K11: Not tested | L11: High | M11: High | O11: Token validation
A12: API-ADMIN-PERM-LIST-009 | B12: (TS-API-007) Admin API Functionality | C12: Access with tampered JWT | D12: GET | E12: /v1/admin/permissions/list | G12: Invalid token | H12: Send GET request | I12: Status Code "401 Unauthorized" with Unauthenticated message | K12: Not tested | L12: High | M12: High | O12: JWT integrity
A13: API-ADMIN-PERM-LIST-010 | B13: (TS-API-007) Admin API Functionality | C13: IDOR validation | D13: GET | E13: /v1/admin/permissions/list | G13: Different organization admin | H13: Send GET request | I13: Only permissions for authorized scope returned | K13: Not tested | L13: High | M13: High | O13: Data isolation
A14: API-ADMIN-PERM-LIST-011 | B14: (TS-API-007) Admin API Functionality | C14: Response time validation | D14: GET | E14: /v1/admin/permissions/list | G14: System under normal load | H14: Send GET request | I14: Response within SLA (≤2 sec) | J14: As expected | K14: Pass | L14: Low | M14: Low | O14: Performance
A15: API-ADMIN-PERM-LIST-012 | B15: (TS-API-007) Admin API Functionality | C15: Server failure handling | D15: GET | E15: /v1/admin/permissions/list | G15: DB/service unavailable | H15: Send GET request | I15: Status Code "500 Internal Server Error" With Proper Message | J15: As expected | K15: Pass | L15: High | M15: High | O15: Error handling
A16: API-ADMIN-PERM-LIST-013 | B16: (TS-API-007) Admin API Functionality | C16: Ensure no duplicate permission IDs | D16: GET | E16: /v1/admin/permissions/list | G16: Admin authenticated | H16: Send GET request | I16: No duplicate IDs within same model | J16: As expected | K16: Pass | L16: Medium | M16: Medium | O16: Data consistency
A17: API-ADMIN-PERM-LIST-014 | B17: (TS-API-007) Admin API Functionality | C17: Large number of permissions | D17: GET | E17: /v1/admin/permissions/list | G17: 1000+ permissions exist | H17: Send GET request | I17: API returns complete list without truncation | K17: Not tested | L17: Medium | M17: Medium | O17: Scalability
B18: Assign Permissions To An Existing Role
A19: API-ADMIN-ASSIGN-PERM-015 | B19: (TS-API-007) Admin API Functionality | C19: Assign permission to existing role | D19: POST | E19: /v1/admin/roles/permissions | F19: role="manager", permissionIds=[1] | G19: Admin authenticated, role exists | H19: Send POST request with valid payload | I19: Status Code "200 OK", response contains name, permissions_count, and permissions grouped by model | J19: Status 200 OK returned with expected response | K19: Pass | L19: High | M19: High | O19: Positive case
A20: API-ADMIN-ASSIGN-PERM-016 | B20: (TS-API-007) Admin API Functionality | C20: Assign multiple permissions | D20: POST | E20: /v1/admin/roles/permissions | F20: permissionIds=[1,5,7] | G20: Role exists | H20: Send POST request | I20: All permissions reflected in response | J20: All assigned permission displayed successfully in response body | K20: Pass | L20: High | M20: High | O20: Multiple entries
A21: API-ADMIN-ASSIGN-PERM-017 | B21: (TS-API-007) Admin API Functionality | C21: Validate permissions_count accuracy | D21: POST | E21: /v1/admin/roles/permissions | F21: Valid payload | G21: Role exists | H21: Send POST request | I21: permissions_count equals total assigned permissions | J21: Permission count is accurate | K21: Pass | L21: High | M21: High | O21: Data validation
A22: API-ADMIN-ASSIGN-PERM-018 | B22: (TS-API-007) Admin API Functionality | C22: Validate response schema | D22: POST | E22: /v1/admin/roles/permissions | F22: Valid payload | G22: Role exists | H22: Send POST request | I22: Response contains name, permissions_count, permissions object | J22: As expected | K22: Pass | L22: Medium | M22: High | O22: Schema validation
A23: API-ADMIN-ASSIGN-PERM-019 | B23: (TS-API-007) Admin API Functionality | C23: Missing role field | D23: POST | E23: /v1/admin/roles/permissions | F23: permissionIds=[1] | G23: Admin authenticated | H23: Send request without role | I23: Validation error message must be displayed | J23: 422 validation error is displayed | K23: Pass | L23: High | M23: High | O23: Required field
A24: API-ADMIN-ASSIGN-PERM-020 | B24: (TS-API-007) Admin API Functionality | C24: Missing permissionIds field | D24: POST | E24: /v1/admin/roles/permissions | F24: role="manager" | G24: Admin authenticated | H24: Send request without permissionIds | I24: Validation error message must be displayed | J24: As expected | K24: Pass | L24: High | M24: High | O24: Required field
A25: API-ADMIN-ASSIGN-PERM-021 | B25: (TS-API-007) Admin API Functionality | C25: Empty permissionIds array | D25: POST | E25: /v1/admin/roles/permissions | F25: permissionIds=[] | G25: Role exists | H25: Send POST request | I25: Validation error message must be displayed | J25: Validation error for mandatory field is displayed | K25: Pass | L25: Medium | M25: Medium | O25: Boundary case
A26: API-ADMIN-ASSIGN-PERM-022 | B26: (TS-API-007) Admin API Functionality | C26: Invalid role name | D26: POST | E26: /v1/admin/roles/permissions | F26: role="invalidRole" | G26: Admin authenticated | H26: Send POST request | I26: Status Code "422 Unprocessable Entity" | J26: As expected | K26: Pass | L26: Medium | M26: Medium | O26: Role validation
A27: API-ADMIN-ASSIGN-PERM-023 | B27: (TS-API-007) Admin API Functionality | C27: Invalid permission ID | D27: POST | E27: /v1/admin/roles/permissions | F27: permissionIds=[999] | G27: Role exists | H27: Send POST request | I27: Status Code "422 Unprocessable Entity" | J27: As expected | K27: Pass | L27: Medium | M27: Medium | O27: Permission validation
A28: API-ADMIN-ASSIGN-PERM-024 | B28: (TS-API-007) Admin API Functionality | C28: Duplicate permission IDs | D28: POST | E28: /v1/admin/roles/permissions | F28: permissionIds=[1,1] | G28: Role exists | H28: Send POST request | I28: Duplicate ignored or validation error | J28: Duplicate ignored as expected | K28: Pass | L28: Low | M28: Low | O28: Data integrity
A29: API-ADMIN-ASSIGN-PERM-025 | B29: (TS-API-007) Admin API Functionality | C29: Without authentication | D29: POST | E29: /v1/admin/roles/permissions | F29: Valid payload | G29: User not logged in | H29: Send POST request | I29: Status Code "401 Unauthorized" | J29: Unauthorized message displayed | K29: Pass | L29: High | M29: High | O29: Authentication
A30: API-ADMIN-ASSIGN-PERM-026 | B30: (TS-API-007) Admin API Functionality | C30: Without admin permission | D30: POST | E30: /v1/admin/roles/permissions | F30: Valid payload | G30: Logged in as normal user | H30: Send POST request | I30: Status Code "403 Forbidden" | K30: Not tested | L30: High | M30: High | O30: RBAC
A31: API-ADMIN-ASSIGN-PERM-027 | B31: (TS-API-007) Admin API Functionality | C31: Expired token | D31: POST | E31: /v1/admin/roles/permissions | F31: Valid payload | G31: Token expired | H31: Send POST request | I31: Status Code "401 Unauthorized" | J31: As expected | K31: Pass | L31: High | M31: High | O31: Token validation
A32: API-ADMIN-ASSIGN-PERM-028 | B32: (TS-API-007) Admin API Functionality | C32: Tampered JWT token | D32: POST | E32: /v1/admin/roles/permissions | F32: Valid payload | G32: Invalid token | H32: Send POST request | I32: Status Code "401 Unauthorized" | K32: Not tested | L32: High | M32: High | O32: JWT integrity
A33: API-ADMIN-ASSIGN-PERM-029 | B33: (TS-API-007) Admin API Functionality | C33: IDOR attempt (other organization role) | D33: POST | E33: /v1/admin/roles/permissions | F33: Role from another org | G33: Multi-tenant system | H33: Send POST request | I33: Status Code "403 Forbidden" | K33: Not tested | L33: Critical | M33: High | O33: Data isolation
A34: API-ADMIN-ASSIGN-PERM-030 | B34: (TS-API-007) Admin API Functionality | C34: Large number of permissions | D34: POST | E34: /v1/admin/roles/permissions | F34: 1000+ permissionIds | G34: Role exists | H34: Send POST request | I34: Processed successfully within SLA | K34: Not tested | L34: Medium | M34: Medium | O34: Scalability
A35: API-ADMIN-ASSIGN-PERM-031 | B35: (TS-API-007) Admin API Functionality | C35: Response time validation | D35: POST | E35: /v1/admin/roles/permissions | F35: Valid payload | G35: Normal system load | H35: Send POST request | I35: Response ≤ 2 seconds | J35: As expected | K35: Pass | L35: Low | M35: Low | O35: SLA validation
A36: API-ADMIN-ASSIGN-PERM-032 | B36: (TS-API-007) Admin API Functionality | C36: Database failure handling | D36: POST | E36: /v1/admin/roles/permissions | F36: Valid payload | G36: DB unavailable | H36: Send POST request | I36: Status Code "500 Internal Server Error" | K36: Not tested | L36: High | M36: High | O36: Error handling
A37: API-ADMIN-ASSIGN-PERM-033 | B37: (TS-API-007) Admin API Functionality | C37: Verify permissions after assignment | D37: GET | E37: /v1/admin/roles/{role}/permissions | F37: role="manager" | G37: Permissions assigned | H37: Retrieve permissions | I37: Assigned permissions visible in response | J37: Assigned permission is visible in response body | K37: Pass | L37: High | M37: High | O37: Post-condition validation

Sheet ChecklistAPI
A1: <<<TestScenario | B1: <<<APITestScenario
A2: Test Case ID | B2: Test Scenario | C2: Test Case Title | D2: Method | E2: API Endpoints | F2: Test Data | G2: Pre-requisites | H2: Test Steps | I2: Expected Result | J2: Actual Result | K2: Execution Status | L2: Severity | M2: Priority | N2: Attachments | O2: Notes
A3: Show An Existing Checklist
A4: API-GET-CHECKLIST-ID-001 | B4: (TS-API-002) Checklists API Functionality | C4: Retrieve checklist with valid ULID | D4: GET | E4: /v1/checklists/{checklist} | F4: checklist = valid ULID | G4: Checklist exists, user authenticated | H4: 1. Send GET request with valid ULID | I4: Status Code "200 OK", response contains ulid, name, type | J4: Checklist matched with ULID is returned | K4: Pass | L4: High | M4: High | O4: Positive test case
A5: API-GET-CHECKLIST-ID-002 | B5: (TS-API-002) Checklists API Functionality | C5: Retrieve non-existing checklist | D5: GET | E5: /v1/checklists/{checklist} | F5: checklist = non-existing ULID | G5: User authenticated | H5: Send GET request | I5: Status Code "404 Not Found", checklist not found | J5: Checklist not found | K5: Pass | L5: Medium | M5: Medium | O5: Negative test
A6: API-GET-CHECKLIST-ID-003 | B6: (TS-API-002) Checklists API Functionality | C6: Retrieve checklist with invalid ULID format | D6: GET | E6: /v1/checklists/{checklist} | F6: checklist = %4%%4% | G6: User authenticated | H6: Send GET request | I6: Status Code "400 Bad Request", invalid ULID format | J6: Bad request response returned | K6: Pass | L6: Medium | M6: Medium | O6: Validation
A7: API-GET-CHECKLIST-ID-004 | B7: (TS-API-002) Checklists API Functionality | C7: Retrieve checklist without authentication | D7: GET | E7: /v1/checklists/{checklist} | F7: checklist = valid ULID | G7: User not authenticated | H7: Send GET request | I7: Status Code "401 Unauthorized" with Unauthenticated message | J7: Unauthorized returned | K7: Pass | L7: High | M7: High | O7: Security
A8: API-GET-CHECKLIST-ID-005 | B8: (TS-API-002) Checklists API Functionality | C8: Retrieve checklist without permission | D8: GET | E8: /v1/checklists/{checklist} | F8: checklist = valid ULID | G8: User lacks permission | H8: Send GET request | I8: Status Code "403 Forbidden" with proper message | K8: Not tested | L8: High | M8: High | O8: Authorization
A9: API-GET-CHECKLIST-ID-006 | B9: (TS-API-002) Checklists API Functionality | C9: Verify response schema | D9: GET | E9: /v1/checklists/{checklist} | F9: checklist = valid ULID | G9: Checklist exists | H9: Send GET request | I9: Response matches schema (ulid, name, type) | J9: As expected | K9: Pass | L9: Low | M9: Low | O9: Schema validation
A10: API-GET-CHECKLIST-ID-007 | B10: (TS-API-002) Checklists API Functionality | C10: Verify data accuracy | D10: GET | E10: /v1/checklists/{checklist} | F10: checklist = valid ULID | G10: Checklist exists | H10: Send GET request | I10: Response values match DB records | J10: As expected | K10: Pass | L10: Medium | M10: Medium | O10: Data integrity
A11: API-GET-CHECKLIST-ID-008 | B11: (TS-API-002) Checklists API Functionality | C11: Content-Type header validation | D11: GET | E11: /v1/checklists/{checklist} | F11: valid ULID | G11: Checklist exists | H11: Send GET request | I11: Content-Type: application/json | J11: As expected | K11: Pass | L11: Low | M11: Low | O11: Header validation
A12: API-GET-CHECKLIST-ID-009 | B12: (TS-API-002) Checklists API Functionality | C12: Server error handling | D12: GET | E12: /v1/checklists/{checklist} | F12: valid ULID | G12: DB/service down | H12: Send GET request | I12: Status Code "500 Internal Server Error" | J12: Internal server error message displayed | K12: Pass | L12: High | M12: High | O12: Reliability
A13: Show All Exisitng Checklist
A14: API-GET-ALL-CHECKLIST-001 | B14: (TS-API-002) Checklists API Functionality | C14: Retrieve all checklists successfully | D14: GET | E14: v1/checklists/list | F14: N/A | G14: User authenticated, checklists exist | H14: 1. Send GET request | I14: 200 OK, list of checklists returned | J14: All checklist are returned successfully | K14: Pass | L14: High | M14: High | O14: Positive test case
A15: API-GET-ALL-CHECKLIST-002 | B15: (TS-API-002) Checklists API Functionality | C15: Verify response structure | D15: GET | E15: v1/checklists/list | F15: N/A | G15: Checklists exist | H15: Send GET request | I15: Each checklist contains ulid, name, type | J15: As expected | K15: Pass | L15: Low | M15: Low | O15: Schema validation
A16: API-GET-ALL-CHECKLIST-003 | B16: (TS-API-002) Checklists API Functionality | C16: Retrieve checklist list when no records exist | D16: GET | E16: v1/checklists/list | F16: N/A | G16: No checklist available | H16: Send GET request | I16: 200 OK, empty list returned | J16: Empty list exists | K16: Pass | L16: Medium | M16: Medium | O16: Edge case
A17: API-GET-ALL-CHECKLIST-004 | B17: (TS-API-002) Checklists API Functionality | C17: Retrieve checklist list without authentication | D17: GET | E17: v1/checklists/list | F17: N/A | G17: User not authenticated | H17: Send GET request | I17: 401 Unauthorized | J17: Unauhorized message displayed | K17: Pass | L17: High | M17: High | O17: Security
A18: API-GET-ALL-CHECKLIST-005 | B18: (TS-API-002) Checklists API Functionality | C18: Retrieve checklist list without permission | D18: GET | E18: v1/checklists/list | F18: N/A | G18: User lacks permission | H18: Send GET request | I18: 403 Forbidden | K18: Not tested | L18: High | M18: High | O18: Authorization
A19: API-GET-ALL-CHECKLIST-006 | B19: (TS-API-002) Checklists API Functionality | C19: Performance – response time | D19: GET | E19: v1/checklists/list | F19: N/A | G19: Large number of records | H19: Send GET request | I19: Response within SLA | J19: As expected | K19: Pass | L19: Low | M19: Low | O19: Performance
A20: API-GET-ALL-CHECKLIST-007 | B20: (TS-API-002) Checklists API Functionality | C20: Content-Type validation | D20: GET | E20: v1/checklists/list | F20: N/A | G20: Checklists exist | H20: Send GET request | I20: Content-Type: application/json | J20: As expected | K20: Pass | L20: Low | M20: Low | O20: Header validation
A21: API-GET-ALL-CHECKLIST-008 | B21: (TS-API-002) Checklists API Functionality | C21: Server error handling | D21: GET | E21: v1/checklists/list | F21: N/A | G21: DB/service down | H21: Send GET request | I21: 500 Internal Server Error | J21: As expected | K21: Pass | L21: High | M21: High | O21: Reliability
A22: Add A Checklist
A23: API-ADD-CHECKLIST-001 | B23: (TS-API-002) Checklists API Functionality | C23: Add checklist with valid data | D23: POST | E23: /v1/checklists | F23: name = "Laptop Request", type = 1 | G23: User authenticated | H23: Send POST request with valid payload | I23: Status Code "201 Created", checklist created and response contains ulid, name, type | J23: New checklist added successfully | K23: Pass | L23: High | M23: High | O23: Positive test case
A24: API-ADD-CHECKLIST-002 | B24: (TS-API-002) Checklists API Functionality | C24: Add checklist with missing name | D24: POST | E24: /v1/checklists | F24: type = 1 | G24: User authenticated | H24: Send POST request without name | I24: Status Code "422 Unprocessable Entity" with validation error for name | J24: Validation error displayed as expected | K24: Pass | L24: High | M24: High | O24: Field validation
A25: API-ADD-CHECKLIST-003 | B25: (TS-API-002) Checklists API Functionality | C25: Add checklist with missing type | D25: POST | E25: /v1/checklists | F25: name = "Laptop Request" | G25: User authenticated | H25: Send POST request without type | I25: Status Code "422 Unprocessable Entity" with validation error for type | J25: As expected | K25: Pass | L25: High | M25: High | O25: Field validation
A26: API-ADD-CHECKLIST-004 | B26: (TS-API-002) Checklists API Functionality | C26: Add checklist with invalid type value | D26: POST | E26: /v1/checklists | F26: name="Laptop Request", type=99 | G26: User authenticated | H26: Send POST request with invalid type | I26: Status Code "400 Bad Request", invalid type error | J26: Invalid type error displayed | K26: Pass | L26: Medium | M26: Medium | O26: Enum validation
A27: API-ADD-CHECKLIST-005 | B27: (TS-API-002) Checklists API Functionality | C27: Add checklist with duplicate name | D27: POST | E27: /v1/checklists | F27: name = existing checklist | G27: Checklist already exists | H27: Send POST request | I27: Status Code "409 Conflict", duplicate checklist error | J27: Duplicate checklist error displayed as expected | K27: Pass | L27: Medium | M27: Medium | O27: Uniqueness check
A28: API-ADD-CHECKLIST-006 | B28: (TS-API-002) Checklists API Functionality | C28: Add checklist with empty payload | D28: POST | E28: /v1/checklists | F28: {} | G28: User authenticated | H28: Send POST request with empty payload | I28: Status Code "422 Unprocessable Entity" | J28: As expected | K28: Pass | L28: Medium | M28: Medium | O28: Negative case
A29: API-ADD-CHECKLIST-007 | B29: (TS-API-002) Checklists API Functionality | C29: Add checklist without authentication | D29: POST | E29: /v1/checklists | F29: Valid payload | G29: User not authenticated | H29: Send POST request | I29: Status Code "401 Unauthorized" | J29: Unaauthorized messgae displayed | K29: Pass | L29: High | M29: High | O29: Security
A30: API-ADD-CHECKLIST-008 | B30: (TS-API-002) Checklists API Functionality | C30: Add checklist without permission | D30: POST | E30: /v1/checklists | F30: Valid payload | G30: User lacks permission | H30: Send POST request | I30: Status Code "403 Forbidden" | K30: Not tested | L30: High | M30: High | O30: Authorization
A31: API-ADD-CHECKLIST-009 | B31: (TS-API-002) Checklists API Functionality | C31: Verify response schema | D31: POST | E31: /v1/checklists | F31: Valid payload | G31: Checklist created | H31: Send POST request | I31: Response contains ulid, name, type | J31: Response body contains required objects | K31: Pass | L31: Low | M31: Low | O31: Schema validation
A32: API-ADD-CHECKLIST-010 | B32: (TS-API-002) Checklists API Functionality | C32: Performance – checklist creation time | D32: POST | E32: /v1/checklists | F32: Valid payload | G32: System under normal load | H32: Send POST request | I32: Response within SLA (≤2 sec) | K32: Not tested | L32: Low | M32: Low | O32: Performance
A33: API-ADD-CHECKLIST-011 | B33: (TS-API-002) Checklists API Functionality | C33: Server error handling | D33: POST | E33: /v1/checklists | F33: Valid payload | G33: DB/service unavailable | H33: Send POST request | I33: Status Code "500 Internal Server Error" | J33: As expected | K33: Pass | L33: High | M33: High | O33: Reliability
A34: Get Checklist
A35: API-GET-CHECKLIST-001 | B35: (TS-API-002) Checklists API Functionality | C35: Retrieve checklist with valid filters | D35: GET | E35: /v1/checklists | F35: page=1, perPage=10, name="", type=1 | G35: User authenticated, checklists exist | H35: Send GET request with valid query params | I35: Status Code "200 OK", filtered checklist list returned | J35: All checklist mathed with type 1 is displayed successfully | K35: Pass | L35: High | M35: High | O35: Positive test case
A36: API-GET-CHECKLIST-002 | B36: (TS-API-002) Checklists API Functionality | C36: Retrieve checklist with pagination only | D36: GET | E36: /v1/checklists | F36: page=1, perPage=10 | G36: User authenticated | H36: Send GET request with pagination params | I36: Status Code "200 OK", paginated results returned | J36: As expected | K36: Pass | L36: Medium | M36: Medium | O36: Pagination
A37: API-GET-CHECKLIST-003 | B37: (TS-API-002) Checklists API Functionality | C37: Filter checklist by name | D37: GET | E37: /v1/checklists | F37: name="Laptop" | G37: User authenticated | H37: Send GET request with name filter | I37: Matching checklists returned | J37: Matching checklists are returned | K37: Pass | L37: Medium | M37: Medium | O37: Search
A38: API-GET-CHECKLIST-004 | B38: (TS-API-002) Checklists API Functionality | C38: Filter checklist by type | D38: GET | E38: /v1/checklists | F38: type=1 | G38: User authenticated | H38: Send GET request with type filter | I38: Only type=1 checklists returned | J38: As expected | K38: Pass | L38: Medium | M38: Medium | O38: Enum filter
A39: API-GET-CHECKLIST-005 | B39: (TS-API-002) Checklists API Functionality | C39: Filter checklist with no matching records | D39: GET | E39: /v1/checklists | F39: name="XYZ" | G39: User authenticated | H39: Send GET request | I39: Status Code "200 OK" empty list returned | J39: Empty array returned | K39: Pass | L39: Low | M39: Low | O39: Edge case
A40: API-GET-CHECKLIST-006 | B40: (TS-API-002) Checklists API Functionality | C40: Invalid page number | D40: GET | E40: /v1/checklists | F40: page=-1 | G40: User authenticated | H40: Send GET request | I40: Status Code "400 Bad Request" with proper message stating invalid page | J40: Initial page returns | K40: Fail | L40: Medium | M40: Medium | O40: Validation
...

Sheet DepartmentAPI
A1: <<<TestScenario | B1: <<<APITestScenario
A2: Test Case ID | B2: Test Scenario | C2: Test Case Title | D2: Method | E2: API Endpoints | F2: Test Data | G2: Pre-requisites | H2: Test Steps | I2: Expected Result | J2: Actual Result | K2: Execution Status | L2: Severity | M2: Priority | N2: Attachments | O2: Notes
A3: Show All Existing Department
A4: API-FETCH-ALL -DEPT-001 | B4: (TS-API-003) Department API Functionality | C4: Fetch list of all departments successfully | D4: GET | E4: /v1/departments/list | F4: N/A | G4: Valid auth token | H4: Send GET request | I4: 200 OK, list of departments returned | J4: All list of departments are displyed | K4: Pass | L4: N/A | M4: N/A
A5: API-FETCH-ALL -DEPT-002 | B5: (TS-API-003) Department API Functionality | C5: Validate department response schema | D5: GET | E5: /v1/departments/list | F5: N/A | G5: Valid auth token | H5: Send GET request | I5: Each department contains ulid and name | J5: As expected | K5: Pass | L5: N/A | M5: N/A
A6: API-FETCH-ALL -DEPT-003 | B6: (TS-API-003) Department API Functionality | C6: Verify ULID format | D6: GET | E6: /v1/departments/list | F6: N/A | G6: Valid auth token | H6: Send request | I6: ulid is non-empty and valid string | J6: As expected | K6: Pass | L6: N/A | M6: N/A
A7: API-FETCH-ALL -DEPT-004 | B7: (TS-API-003) Department API Functionality | C7: Verify department name is not null | D7: GET | E7: /v1/departments/list | F7: N/A | G7: Valid auth token | H7: Send request | I7: name is non-empty string | J7: As expected | K7: Pass | L7: N/A | M7: N/A
A8: API-FETCH-ALL -DEPT-005 | B8: (TS-API-003) Department API Functionality | C8: Fetch departments without authentication | D8: GET | E8: /v1/departments/list | F8: N/A | G8: No token | H8: Send request | I8: 401 Unauthorized | J8: Unauthorized message returned | K8: Pass | L8: N/A | M8: N/A
A9: API-FETCH-ALL -DEPT-006 | B9: (TS-API-003) Department API Functionality | C9: Fetch departments with invalid token | D9: GET | E9: /v1/departments/list | F9: N/A | G9: Invalid token | H9: Send request | I9: 401 Unauthorized | J9: As expected | K9: Pass | L9: N/A | M9: N/A
A10: API-FETCH-ALL -DEPT-007 | B10: (TS-API-003) Department API Functionality | C10: Fetch departments with insufficient permission | D10: GET | E10: /v1/departments/list | F10: N/A | G10: Valid token, no permission | H10: Send request | I10: 403 Forbidden | K10: Not tested | L10: N/A | M10: N/A
A11: API-FETCH-ALL -DEPT-008 | B11: (TS-API-003) Department API Functionality | C11: No departments exist in system | D11: GET | E11: /v1/departments/list | F11: N/A | G11: Valid token, empty DB | H11: Send request | I11: 404 Not Found | K11: Not tested | L11: N/A | M11: N/A
A12: API-FETCH-ALL -DEPT-009 | B12: (TS-API-003) Department API Functionality | C12: Verify response type is array | D12: GET | E12: /v1/departments/list | F12: N/A | G12: Valid auth token | H12: Send request | I12: Response is an array of objects | J12: Response type is array | K12: Pass | L12: N/A | M12: N/A
A13: API-FETCH-ALL -DEPT-010 | B13: (TS-API-003) Department API Functionality | C13: Verify response content type | D13: GET | E13: /v1/departments/list | F13: N/A | G13: Valid auth token | H13: Send request | I13: Content-Type is application/json | J13: As expected | K13: Pass | L13: N/A | M13: N/A
A14: API-FETCH-ALL -DEPT-011 | B14: (TS-API-003) Department API Functionality | C14: Verify duplicate department entries are not returned | D14: GET | E14: /v1/departments/list | F14: N/A | G14: Valid auth token | H14: Send request | I14: No duplicate ulid values | J14: As expected | K14: Pass | L14: N/A | M14: N/A
A15: API-FETCH-ALL -DEPT-012 | B15: (TS-API-003) Department API Functionality | C15: Performance check for department list | D15: GET | E15: /v1/departments/list | F15: N/A | G15: Valid auth token | H15: Send request | I15: Response within acceptable time | J15: As expected | K15: Pass | L15: N/A | M15: N/A
A16: Get Department
A17: API-GET-DEPART-013 | B17: (TS-API-003) Department API Functionality | C17: Fetch department with valid page,perPage, and name | D17: GET | E17: /v1/departments | F17: page=1, per_page=2, name=HR | G17: Valid auth token | H17: Send GET request | I17: 200 OK, returns department matching name | J17: Mathing department returned with correct pagination | K17: Pass | L17: N/A | M17: N/A
A18: API-GET-DEPART-014 | B18: (TS-API-003) Department API Functionality | C18: Fetch department with valid name only | D18: GET | E18: /v1/departments | F18: name=HR | G18: Valid auth token | H18: Send GET request | I18: 200 OK, returns all matching departments | J18: As expected | K18: Pass | L18: N/A | M18: N/A
A19: API-GET-DEPART-015 | B19: (TS-API-003) Department API Functionality | C19: fetch department with department only | D19: GET | E19: /v1/departments | F19: page=1, per_page=2 | G19: Valid auth token | H19: Send GET request | I19: 200 OK, first 2 departments returned | J19: First 2 departments returned | K19: Pass | L19: N/A | M19: N/A
A20: API-GET-DEPART-016 | B20: (TS-API-003) Department API Functionality | C20: Fetch department with non-existing name | D20: GET | E20: /v1/departments | F20: name=NonExist | G20: Valid auth token | H20: Send GET request | I20: 404 Not Found | J20: As expected | K20: Pass | L20: N/A | M20: N/A
A21: API-GET-DEPART-017 | B21: (TS-API-003) Department API Functionality | C21: Fetch department with page beyond last | D21: GET | E21: /v1/departments | F21: page=99, per_page=2, name=HR | G21: Valid auth token | H21: Send GET request | I21: 404 Not Found or empty array | J21: Empty array returned | K21: Pass | L21: N/A | M21: N/A
A22: API-GET-DEPART-018 | B22: (TS-API-003) Department API Functionality | C22: Fetch department without authorization | D22: GET | E22: /v1/departments | F22: page=1, per_page=2, name=HR | G22: No token | H22: Send GET request | I22: 401 Unauthorized | J22: Unauthorized message returned | K22: Pass | L22: N/A | M22: N/A
A23: API-GET-DEPART-019 | B23: (TS-API-003) Department API Functionality | C23: Fetch department with invalid token | D23: GET | E23: /v1/departments | F23: page=1, per_page=2, name=HR | G23: Invalid token | H23: Send GET request | I23: 401 Unauthorized | J23: As expected | K23: Pass | L23: N/A | M23: N/A
A24: API-GET-DEPART-020 | B24: (TS-API-003) Department API Functionality | C24: Fetch department with insufficient permission | D24: GET | E24: /v1/departments | F24: page=1, per_page=2, name=HR | G24: User lacks permission | H24: Send GET request | I24: 403 Forbidden | K24: Not tested | L24: N/A | M24: N/A
